Workbook

Sheet ROYCCA
A1: ROYCCA | L1: ACSS | S1: LVTS
B2: ACSS +USBE | E2: LVTS | L2: Point Forecast | M2: Lo 95 | N2: Hi 95 | O2: Lo 95 | P2: Point Forecast | Q2: Hi 95 | S2: Point Forecast | T2: Lo 95 | U2: Hi 95 | V2: Lo 95 | W2: Point Forecast | X2: Hi 95
A3: Year | B3: Lower Bound | C3: Value Forecast (billions) | D3: Upper Bound | E3: Lower Bound | F3: Value Forecast (billions) | G3: Upper Bound | K3: 2022Q1 | L3: 947.21881 | M3: 893.76205 | N3: 1000.6756 | O3: =ROUND(M3,3) -> 893.762 | P3: =ROUND(L3,3) -> 947.219 | Q3: =ROUND(N3,3) -> 1000.676 | R3: =K3 -> 2022Q1 | S3: 12148.825 | T3: 11162.48 | U3: 13135.17 | V3: =ROUND(T3,3) -> 11162.48 | W3: =ROUND(S3,3) -> 12148.825 | X3: =ROUND(U3,3) -> 13135.17
A4: =K3 -> 2022Q1 | B4: =O3 -> 893.762 | C4: =P3 -> 947.219 | D4: =Q3 -> 1000.676 | E4: =V3 -> 11162.48 | F4: =W3 -> 12148.825 | G4: =X3 -> 13135.17 | K4: 2022Q2 | L4: 990.23604 | M4: 919.9075 | N4: 1060.5646 | O4: =ROUND(M4,3) -> 919.907 | P4: =ROUND(L4,3) -> 990.236 | Q4: =ROUND(N4,3) -> 1060.565 | R4: =K4 -> 2022Q2 | S4: 12371.539 | T4: 10836.842 | U4: 13906.236 | V4: =ROUND(T4,3) -> 10836.842 | W4: =ROUND(S4,3) -> 12371.539 | X4: =ROUND(U4,3) -> 13906.236
A5: =K4 -> 2022Q2 | B5: =O4 -> 919.907 | C5: =P4 -> 990.236 | D5: =Q4 -> 1060.565 | E5: =V4 -> 10836.842 | F5: =W4 -> 12371.539 | G5: =X4 -> 13906.236 | I5: =SUM(F5:F8) -> 49420.986 | K5: 2022Q3 | L5: 984.69563 | M5: 904.42142 | N5: 1064.9698 | O5: =ROUND(M5,3) -> 904.421 | P5: =ROUND(L5,3) -> 984.696 | Q5: =ROUND(N5,3) -> 1064.97 | R5: =K5 -> 2022Q3 | S5: 12207.12 | T5: 10209.818 | U5: 14204.421 | V5: =ROUND(T5,3) -> 10209.818 | W5: =ROUND(S5,3) -> 12207.12 | X5: =ROUND(U5,3) -> 14204.421
A6: =K5 -> 2022Q3 | B6: =O5 -> 904.421 | C6: =P5 -> 984.696 | D6: =Q5 -> 1064.97 | E6: =V5 -> 10209.818 | F6: =W5 -> 12207.12 | G6: =X5 -> 14204.421 | I6: =SUM(F9:F12) -> 50982.28 | K6: 2022Q4 | L6: 980.31385 | M6: 893.60633 | N6: 1067.0214 | O6: =ROUND(M6,3) -> 893.606 | P6: =ROUND(L6,3) -> 980.314 | Q6: =ROUND(N6,3) -> 1067.021 | R6: =K6 -> 2022Q4 | S6: 12344.167 | T6: 9942.5079 | U6: 14745.825 | V6: =ROUND(T6,3) -> 9942.508 | W6: =ROUND(S6,3) -> 12344.167 | X6: =ROUND(U6,3) -> 14745.825
A7: =K6 -> 2022Q4 | B7: =O6 -> 893.606 | C7: =P6 -> 980.314 | D7: =Q6 -> 1067.021 | E7: =V6 -> 9942.508 | F7: =W6 -> 12344.167 | G7: =X6 -> 14745.825 | I7: =SUM(F13:F16) -> 52598.873 | K7: 2023Q1 | L7: 924.06788 | M7: 833.02595 | N7: 1015.1098 | O7: =ROUND(M7,3) -> 833.026 | P7: =ROUND(L7,3) -> 924.068 | Q7: =ROUND(N7,3) -> 1015.11 | R7: =K7 -> 2023Q1 | S7: 12498.16 | T7: 9736.3404 | U7: 15259.979 | V7: =ROUND(T7,3) -> 9736.34 | W7: =ROUND(S7,3) -> 12498.16 | X7: =ROUND(U7,3) -> 15259.979
A8: =K7 -> 2023Q1 | B8: =O7 -> 833.026 | C8: =P7 -> 924.068 | D8: =Q7 -> 1015.11 | E8: =V7 -> 9736.34 | F8: =W7 -> 12498.16 | G8: =X7 -> 15259.979 | I8: =SUM(F17:F20) -> 54220.203 | K8: 2023Q2 | L8: 973.79095 | M8: 879.76335 | N8: 1067.8185 | O8: =ROUND(M8,3) -> 879.763 | P8: =ROUND(L8,3) -> 973.791 | Q8: =ROUND(N8,3) -> 1067.819 | R8: =K8 -> 2023Q2 | S8: 12746.624 | T8: 9659.2529 | U8: 15833.996 | V8: =ROUND(T8,3) -> 9659.253 | W8: =ROUND(S8,3) -> 12746.624 | X8: =ROUND(U8,3) -> 15833.996
A9: =K8 -> 2023Q2 | B9: =O8 -> 879.763 | C9: =P8 -> 973.791 | D9: =Q8 -> 1067.819 | E9: =V8 -> 9659.253 | F9: =W8 -> 12746.624 | G9: =X8 -> 15833.996 | I9: =SUM(F21:F24) -> 55841.941 | K9: 2023Q3 | L9: 973.92953 | M9: 877.81773 | N9: 1070.0413 | O9: =ROUND(M9,3) -> 877.818 | P9: =ROUND(L9,3) -> 973.93 | Q9: =ROUND(N9,3) -> 1070.041 | R9: =K9 -> 2023Q3 | S9: 12596.138 | T9: 9210.8168 | U9: 15981.459 | V9: =ROUND(T9,3) -> 9210.817 | W9: =ROUND(S9,3) -> 12596.138 | X9: =ROUND(U9,3) -> 15981.459
A10: =K9 -> 2023Q3 | B10: =O9 -> 877.818 | C10: =P9 -> 973.93 | D10: =Q9 -> 1070.041 | E10: =V9 -> 9210.817 | F10: =W9 -> 12596.138 | G10: =X9 -> 15981.459 | I10: =SUM(F25:F28) -> 57463.712 | K10: 2023Q4 | L10: 974.35713 | M10: 876.77796 | N10: 1071.9363 | O10: =ROUND(M10,3) -> 876.778 | P10: =ROUND(L10,3) -> 974.357 | Q10: =ROUND(N10,3) -> 1071.936 | R10: =K10 -> 2023Q4 | S10: 12740.723 | T10: 9079.8279 | U10: 16401.618 | V10: =ROUND(T10,3) -> 9079.828 | W10: =ROUND(S10,3) -> 12740.723 | X10: =ROUND(U10,3) -> 16401.618
A11: =K10 -> 2023Q4 | B11: =O10 -> 876.778 | C11: =P10 -> 974.357 | D11: =Q10 -> 1071.936 | E11: =V10 -> 9079.828 | F11: =W10 -> 12740.723 | G11: =X10 -> 16401.618 | I11: =SUM(F29:F32) -> 59085.487 | K11: 2024Q1 | L11: 922.1841 | M11: 823.56599 | N11: 1020.8022 | O11: =ROUND(M11,3) -> 823.566 | P11: =ROUND(L11,3) -> 922.184 | Q11: =ROUND(N11,3) -> 1020.802 | R11: =K11 -> 2024Q1 | S11: 12898.795 | T11: 8980.7491 | U11: 16816.841 | V11: =ROUND(T11,3) -> 8980.749 | W11: =ROUND(S11,3) -> 12898.795 | X11: =ROUND(U11,3) -> 16816.841
A12: =K11 -> 2024Q1 | B12: =O11 -> 823.566 | C12: =P11 -> 922.184 | D12: =Q11 -> 1020.802 | E12: =V11 -> 8980.749 | F12: =W11 -> 12898.795 | G12: =X11 -> 16816.841 | K12: 2024Q2 | L12: 975.35643 | M12: 875.99988 | N12: 1074.713 | O12: =ROUND(M12,3) -> 876 | P12: =ROUND(L12,3) -> 975.356 | Q12: =ROUND(N12,3) -> 1074.713 | R12: =K12 -> 2024Q2 | S12: 13149.467 | T12: 8989.6712 | U12: 17309.262 | V12: =ROUND(T12,3) -> 8989.671 | W12: =ROUND(S12,3) -> 13149.467 | X12: =ROUND(U12,3) -> 17309.262
A13: =K12 -> 2024Q2 | B13: =O12 -> 876 | C13: =P12 -> 975.356 | D13: =Q12 -> 1074.713 | E13: =V12 -> 8989.671 | F13: =W12 -> 13149.467 | G13: =X12 -> 17309.262 | K13: 2024Q3 | L13: 978.41609 | M13: 878.5333 | N13: 1078.2989 | O13: =ROUND(M13,3) -> 878.533 | P13: =ROUND(L13,3) -> 978.416 | Q13: =ROUND(N13,3) -> 1078.299 | R13: =K13 -> 2024Q3 | S13: 13000.174 | T13: 8611.6871 | U13: 17388.661 | V13: =ROUND(T13,3) -> 8611.687 | W13: =ROUND(S13,3) -> 13000.174 | X13: =ROUND(U13,3) -> 17388.661
A14: =K13 -> 2024Q3 | B14: =O13 -> 878.533 | C14: =P13 -> 978.416 | D14: =Q13 -> 1078.299 | E14: =V13 -> 8611.687 | F14: =W13 -> 13000.174 | G14: =X13 -> 17388.661 | K14: 2024Q4 | L14: 981.31748 | M14: 881.05898 | N14: 1081.576 | O14: =ROUND(M14,3) -> 881.059 | P14: =ROUND(L14,3) -> 981.317 | Q14: =ROUND(N14,3) -> 1081.576 | R14: =K14 -> 2024Q4 | S14: 13145.405 | T14: 8539.4446 | U14: 17751.366 | V14: =ROUND(T14,3) -> 8539.445 | W14: =ROUND(S14,3) -> 13145.405 | X14: =ROUND(U14,3) -> 17751.366
A15: =K14 -> 2024Q4 | B15: =O14 -> 881.059 | C15: =P14 -> 981.317 | D15: =Q14 -> 1081.576 | E15: =V14 -> 8539.445 | F15: =W14 -> 13145.405 | G15: =X14 -> 17751.366 | K15: 2025Q1 | L15: 931.23943 | M15: 830.71234 | N15: 1031.7665 | O15: =ROUND(M15,3) -> 830.712 | P15: =ROUND(L15,3) -> 931.239 | Q15: =ROUND(N15,3) -> 1031.767 | R15: =K15 -> 2025Q1 | S15: 13303.827 | T15: 8490.1432 | U15: 18117.51 | V15: =ROUND(T15,3) -> 8490.143 | W15: =ROUND(S15,3) -> 13303.827 | X15: =ROUND(U15,3) -> 18117.51
A16: =K15 -> 2025Q1 | B16: =O15 -> 830.712 | C16: =P15 -> 931.239 | D16: =Q15 -> 1031.767 | E16: =V15 -> 8490.143 | F16: =W15 -> 13303.827 | G16: =X15 -> 18117.51 | K16: 2025Q2 | L16: 986.18595 | M16: 885.46665 | N16: 1086.9052 | O16: =ROUND(M16,3) -> 885.467 | P16: =ROUND(L16,3) -> 986.186 | Q16: =ROUND(N16,3) -> 1086.905 | R16: =K16 -> 2025Q2 | S16: 13554.687 | T16: 8541.8483 | U16: 18567.526 | V16: =ROUND(T16,3) -> 8541.848 | W16: =ROUND(S16,3) -> 13554.687 | X16: =ROUND(U16,3) -> 18567.526
A17: =K16 -> 2025Q2 | B17: =O16 -> 885.467 | C17: =P16 -> 986.186 | D17: =Q16 -> 1086.905 | E17: =V16 -> 8541.848 | F17: =W16 -> 13554.687 | G17: =X16 -> 18567.526 | K17: 2025Q3 | L17: 990.74812 | M17: 889.89121 | N17: 1091.605 | O17: =ROUND(M17,3) -> 889.891 | P17: =ROUND(L17,3) -> 990.748 | Q17: =ROUND(N17,3) -> 1091.605 | R17: =K17 -> 2025Q3 | S17: 13405.497 | T17: 8201.1004 | U17: 18609.894 | V17: =ROUND(T17,3) -> 8201.1 | W17: =ROUND(S17,3) -> 13405.497 | X17: =ROUND(U17,3) -> 18609.894
A18: =K17 -> 2025Q3 | B18: =O17 -> 889.891 | C18: =P17 -> 990.748 | D18: =Q17 -> 1091.605 | E18: =V17 -> 8201.1 | F18: =W17 -> 13405.497 | G18: =X17 -> 18609.894 | K18: 2025Q4 | L18: 994.92194 | M18: 893.96645 | N18: 1095.8774 | O18: =ROUND(M18,3) -> 893.966 | P18: =ROUND(L18,3) -> 994.922 | Q18: =ROUND(N18,3) -> 1095.877 | R18: =K18 -> 2025Q4 | S18: 13550.784 | T18: 8161.6253 | U18: 18939.942 | V18: =ROUND(T18,3) -> 8161.625 | W18: =ROUND(S18,3) -> 13550.784 | X18: =ROUND(U18,3) -> 18939.942
A19: =K18 -> 2025Q4 | B19: =O18 -> 893.966 | C19: =P18 -> 994.922 | D19: =Q18 -> 1095.877 | E19: =V18 -> 8161.625 | F19: =W18 -> 13550.784 | G19: =X18 -> 18939.942 | K19: 2026Q1 | L19: 945.92148 | M19: 844.89536 | N19: 1046.9476 | O19: =ROUND(M19,3) -> 844.895 | P19: =ROUND(L19,3) -> 945.921 | Q19: =ROUND(N19,3) -> 1046.948 | R19: =K19 -> 2026Q1 | S19: 13709.235 | T19: 8141.4376 | U19: 19277.033 | V19: =ROUND(T19,3) -> 8141.438 | W19: =ROUND(S19,3) -> 13709.235 | X19: =ROUND(U19,3) -> 19277.033
A20: =K19 -> 2026Q1 | B20: =O19 -> 844.895 | C20: =P19 -> 945.921 | D20: =Q19 -> 1046.948 | E20: =V19 -> 8141.438 | F20: =W19 -> 13709.235 | G20: =X19 -> 19277.033 | K20: 2026Q2 | L20: 1001.7806 | M20: 900.70381 | N20: 1102.8573 | O20: =ROUND(M20,3) -> 900.704 | P20: =ROUND(L20,3) -> 1001.781 | Q20: =ROUND(N20,3) -> 1102.857 | R20: =K20 -> 2026Q2 | S20: 13960.112 | T20: 8219.2292 | U20: 19700.995 | V20: =ROUND(T20,3) -> 8219.229 | W20: =ROUND(S20,3) -> 13960.112 | X20: =ROUND(U20,3) -> 19700.995
A21: =K20 -> 2026Q2 | B21: =O20 -> 900.704 | C21: =P20 -> 1001.781 | D21: =Q20 -> 1102.857 | E21: =V20 -> 8219.229 | F21: =W20 -> 13960.112 | G21: =X20 -> 19700.995 | K21: 2026Q3 | L21: 1007.1156 | M21: 906.00253 | N21: 1108.2287 | O21: =ROUND(M21,3) -> 906.003 | P21: =ROUND(L21,3) -> 1007.116 | Q21: =ROUND(N21,3) -> 1108.229 | R21: =K21 -> 2026Q3 | S21: 13810.931 | T21: 7902.0288 | U21: 19719.832 | V21: =ROUND(T21,3) -> 7902.029 | W21: =ROUND(S21,3) -> 13810.931 | X21: =ROUND(U21,3) -> 19719.832
A22: =K21 -> 2026Q3 | B22: =O21 -> 906.003 | C22: =P21 -> 1007.116 | D22: =Q21 -> 1108.229 | E22: =V21 -> 7902.029 | F22: =W21 -> 13810.931 | G22: =X21 -> 19719.832 | K22: 2026Q4 | L22: 1011.9439 | M22: 910.80482 | N22: 1113.083 | O22: =ROUND(M22,3) -> 910.805 | P22: =ROUND(L22,3) -> 1011.944 | Q22: =ROUND(N22,3) -> 1113.083 | R22: =K22 -> 2026Q4 | S22: 13956.222 | T22: 7883.9482 | U22: 20028.496 | V22: =ROUND(T22,3) -> 7883.948 | W22: =ROUND(S22,3) -> 13956.222 | X22: =ROUND(U22,3) -> 20028.496
A23: =K22 -> 2026Q4 | B23: =O22 -> 910.805 | C23: =P22 -> 1011.944 | D23: =Q22 -> 1113.083 | E23: =V22 -> 7883.948 | F23: =W22 -> 13956.222 | G23: =X22 -> 20028.496 | K23: 2027Q1 | L23: 963.49773 | M23: 862.33998 | N23: 1064.6555 | O23: =ROUND(M23,3) -> 862.34 | P23: =ROUND(L23,3) -> 963.498 | Q23: =ROUND(N23,3) -> 1064.655 | R23: =K23 -> 2027Q1 | S23: 14114.676 | T23: 7883.3112 | U23: 20346.041 | V23: =ROUND(T23,3) -> 7883.311 | W23: =ROUND(S23,3) -> 14114.676 | X23: =ROUND(U23,3) -> 20346.041
... A34: =K33 -> 2029Q3 | B34: =O33 -> 963.926 | C34: =P33 -> 1065.13 | D34: =Q33 -> 1166.333 | E34: =V33 -> 7385.016 | F34: =W33 -> 15027.261 | G34: =X33 -> 22669.506 | K34: 2029Q4 | L34: 1070.5568 | M34: 969.35298 | N34: 1171.7607 | O34: =ROUND(M34,3) -> 969.353 | P34: =ROUND(L34,3) -> 1070.557 | Q34: =ROUND(N34,3) -> 1171.761 | R34: =K34 -> 2029Q4 | S34: 15172.553 | T34: 7403.2988 | U34: 22941.807 | V34: =ROUND(T34,3) -> 7403.299 | W34: =ROUND(S34,3) -> 15172.553 | X34: =ROUND(U34,3) -> 22941.807
A35: =K34 -> 2029Q4 | B35: =O34 -> 969.353 | C35: =P34 -> 1070.557 | D35: =Q34 -> 1171.761 | E35: =V34 -> 7403.299 | F35: =W34 -> 15172.553 | G35: =X34 -> 22941.807
A38: Mean | C38: =AVERAGE(C4:C35) -> 994.67778 | F38: =AVERAGE(F4:F35) -> 13660.58
A41: ROYCCA (Minus 0.5 Standard Deviation) | K41: ROYCCA (Minus 1 Standard Deviation)
B42: ACSS +USBE | E42: LVTS | L42: ACSS +USBE | O42: LVTS
A43: Year | B43: Lower Bound | C43: Forecast Minus Half A Standard Deviation (billions) | D43: Upper Bound | E43: Lower Bound | F43: =C43 -> Forecast Minus Half A Standard Deviation (billions) | G43: Upper Bound | K43: Year | L43: Lower Bound | M43: Forecast Minus One Standard Deviation (billions) | N43: Upper Bound | O43: Lower Bound | P43: =M43 -> Forecast Minus One Standard Deviation (billions) | Q43: Upper Bound
A44: =A4 -> 2022Q1 | C44: =ROUND(C4-((D4-C4)*(0.5/2)),3) -> 933.855 | F44: =ROUND(F4-((G4-F4)*(0.5/2)),3) -> 11902.239 | K44: =A4 -> 2022Q1 | M44: =ROUND(C4-((D4-C4)*(1/2)),3) -> 920.491 | P44: =ROUND(F4-((G4-F4)*(1/2)),3) -> 11655.653
A45: =A5 -> 2022Q2 | C45: =ROUND(C5-((D5-C5)*(0.5/2)),3) -> 972.654 | F45: =ROUND(F5-((G5-F5)*(0.5/2)),3) -> 11987.865 | K45: =A5 -> 2022Q2 | M45: =ROUND(C5-((D5-C5)*(1/2)),3) -> 955.072 | P45: =ROUND(F5-((G5-F5)*(1/2)),3) -> 11604.191
A46: =A6 -> 2022Q3 | C46: =ROUND(C6-((D6-C6)*(0.5/2)),3) -> 964.628 | F46: =ROUND(F6-((G6-F6)*(0.5/2)),3) -> 11707.795 | K46: =A6 -> 2022Q3 | M46: =ROUND(C6-((D6-C6)*(1/2)),3) -> 944.559 | P46: =ROUND(F6-((G6-F6)*(1/2)),3) -> 11208.47
A47: =A7 -> 2022Q4 | C47: =ROUND(C7-((D7-C7)*(0.5/2)),3) -> 958.637 | F47: =ROUND(F7-((G7-F7)*(0.5/2)),3) -> 11743.753 | K47: =A7 -> 2022Q4 | M47: =ROUND(C7-((D7-C7)*(1/2)),3) -> 936.961 | P47: =ROUND(F7-((G7-F7)*(1/2)),3) -> 11143.338
A48: =A8 -> 2023Q1 | C48: =ROUND(C8-((D8-C8)*(0.5/2)),3) -> 901.308 | F48: =ROUND(F8-((G8-F8)*(0.5/2)),3) -> 11807.705 | K48: =A8 -> 2023Q1 | M48: =ROUND(C8-((D8-C8)*(1/2)),3) -> 878.547 | P48: =ROUND(F8-((G8-F8)*(1/2)),3) -> 11117.251
A49: =A9 -> 2023Q2 | C49: =ROUND(C9-((D9-C9)*(0.5/2)),3) -> 950.284 | F49: =ROUND(F9-((G9-F9)*(0.5/2)),3) -> 11974.781 | K49: =A9 -> 2023Q2 | M49: =ROUND(C9-((D9-C9)*(1/2)),3) -> 926.777 | P49: =ROUND(F9-((G9-F9)*(1/2)),3) -> 11202.938
A50: =A10 -> 2023Q3 | C50: =ROUND(C10-((D10-C10)*(0.5/2)),3) -> 949.902 | F50: =ROUND(F10-((G10-F10)*(0.5/2)),3) -> 11749.808 | K50: =A10 -> 2023Q3 | M50: =ROUND(C10-((D10-C10)*(1/2)),3) -> 925.875 | P50: =ROUND(F10-((G10-F10)*(1/2)),3) -> 10903.478
A51: =A11 -> 2023Q4 | C51: =ROUND(C11-((D11-C11)*(0.5/2)),3) -> 949.962 | F51: =ROUND(F11-((G11-F11)*(0.5/2)),3) -> 11825.499 | K51: =A11 -> 2023Q4 | M51: =ROUND(C11-((D11-C11)*(1/2)),3) -> 925.568 | P51: =ROUND(F11-((G11-F11)*(1/2)),3) -> 10910.276
A52: =A12 -> 2024Q1 | C52: =ROUND(C12-((D12-C12)*(0.5/2)),3) -> 897.53 | F52: =ROUND(F12-((G12-F12)*(0.5/2)),3) -> 11919.284 | K52: =A12 -> 2024Q1 | M52: =ROUND(C12-((D12-C12)*(1/2)),3) -> 872.875 | P52: =ROUND(F12-((G12-F12)*(1/2)),3) -> 10939.772
A53: =A13 -> 2024Q2 | C53: =ROUND(C13-((D13-C13)*(0.5/2)),3) -> 950.517 | F53: =ROUND(F13-((G13-F13)*(0.5/2)),3) -> 12109.518 | K53: =A13 -> 2024Q2 | M53: =ROUND(C13-((D13-C13)*(1/2)),3) -> 925.678 | P53: =ROUND(F13-((G13-F13)*(1/2)),3) -> 11069.57
A54: =A14 -> 2024Q3 | C54: =ROUND(C14-((D14-C14)*(0.5/2)),3) -> 953.445 | F54: =ROUND(F14-((G14-F14)*(0.5/2)),3) -> 11903.052 | K54: =A14 -> 2024Q3 | M54: =ROUND(C14-((D14-C14)*(1/2)),3) -> 928.475 | P54: =ROUND(F14-((G14-F14)*(1/2)),3) -> 10805.931
...

Sheet TDOMCA
A1: TDOMCA | L1: ACSS | S1: LVTS
B2: ACSS +USBE | E2: LVTS | L2: Point Forecast | M2: Lo 95 | N2: Hi 95 | O2: Lo 95 | P2: Point Forecast | Q2: Hi 95 | S2: Point Forecast | T2: Lo 95 | U2: Hi 95 | V2: Lo 95 | W2: Point Forecast | X2: Hi 95
A3: Year | B3: Lower Bound | C3: Value Forecast (billions) | D3: Upper Bound | E3: Lower Bound | F3: Value Forecast (billions) | G3: Upper Bound | K3: 2022Q1 | L3: 768.75331 | M3: 719.78489 | N3: 817.72173 | O3: =ROUND(M3,3) -> 719.785 | P3: =ROUND(L3,3) -> 768.753 | Q3: =ROUND(N3,3) -> 817.722 | R3: =K3 -> 2022Q1 | S3: 7575.5448 | T3: 6762.3733 | U3: 8388.7164 | V3: =ROUND(T3,3) -> 6762.373 | W3: =ROUND(S3,3) -> 7575.545 | X3: =ROUND(U3,3) -> 8388.716
A4: =K3 -> 2022Q1 | B4: =O3 -> 719.785 | C4: =P3 -> 768.753 | D4: =Q3 -> 817.722 | E4: =V3 -> 6762.373 | F4: =W3 -> 7575.545 | G4: =X3 -> 8388.716 | K4: 2022Q2 | L4: 808.6195 | M4: 745.97154 | N4: 871.26747 | O4: =ROUND(M4,3) -> 745.972 | P4: =ROUND(L4,3) -> 808.62 | Q4: =ROUND(N4,3) -> 871.267 | R4: =K4 -> 2022Q2 | S4: 7692.1762 | T4: 6246.1026 | U4: 9138.2498 | V4: =ROUND(T4,3) -> 6246.103 | W4: =ROUND(S4,3) -> 7692.176 | X4: =ROUND(U4,3) -> 9138.25
A5: =K4 -> 2022Q2 | B5: =O4 -> 745.972 | C5: =P4 -> 808.62 | D5: =Q4 -> 871.267 | E5: =V4 -> 6246.103 | F5: =W4 -> 7692.176 | G5: =X4 -> 9138.25 | I5: =SUM(F5:F8) -> 30957.28 | K5: 2022Q3 | L5: 808.12396 | M5: 736.77722 | N5: 879.4707 | O5: =ROUND(M5,3) -> 736.777 | P5: =ROUND(L5,3) -> 808.124 | Q5: =ROUND(N5,3) -> 879.471 | R5: =K5 -> 2022Q3 | S5: 7653.7206 | T5: 5701.6174 | U5: 9605.8239 | V5: =ROUND(T5,3) -> 5701.617 | W5: =ROUND(S5,3) -> 7653.721 | X5: =ROUND(U5,3) -> 9605.824
A6: =K5 -> 2022Q3 | B6: =O5 -> 736.777 | C6: =P5 -> 808.124 | D6: =Q5 -> 879.471 | E6: =V5 -> 5701.617 | F6: =W5 -> 7653.721 | G6: =X5 -> 9605.824 | I6: =SUM(F9:F12) -> 32106.729 | K6: 2022Q4 | L6: 800.0654 | M6: 722.73392 | N6: 877.39688 | O6: =ROUND(M6,3) -> 722.734 | P6: =ROUND(L6,3) -> 800.065 | Q6: =ROUND(N6,3) -> 877.397 | R6: =K6 -> 2022Q4 | S6: 7772.6921 | T6: 5401.3998 | U6: 10143.984 | V6: =ROUND(T6,3) -> 5401.4 | W6: =ROUND(S6,3) -> 7772.692 | X6: =ROUND(U6,3) -> 10143.984
A7: =K6 -> 2022Q4 | B7: =O6 -> 722.734 | C7: =P6 -> 800.065 | D7: =Q6 -> 877.397 | E7: =V6 -> 5401.4 | F7: =W6 -> 7772.692 | G7: =X6 -> 10143.984 | I7: =SUM(F13:F16) -> 33267.722 | K7: 2023Q1 | L7: 752.33563 | M7: 670.73036 | N7: 833.9409 | O7: =ROUND(M7,3) -> 670.73 | P7: =ROUND(L7,3) -> 752.336 | Q7: =ROUND(N7,3) -> 833.941 | R7: =K7 -> 2023Q1 | S7: 7838.6905 | T7: 5106.6885 | U7: 10570.692 | V7: =ROUND(T7,3) -> 5106.689 | W7: =ROUND(S7,3) -> 7838.691 | X7: =ROUND(U7,3) -> 10570.692
A8: =K7 -> 2023Q1 | B8: =O7 -> 670.73 | C8: =P7 -> 752.336 | D8: =Q7 -> 833.941 | E8: =V7 -> 5106.689 | F8: =W7 -> 7838.691 | G8: =X7 -> 10570.692 | I8: =SUM(F17:F20) -> 34428.811 | K8: 2023Q2 | L8: 796.79901 | M8: 712.07615 | N8: 881.52187 | O8: =ROUND(M8,3) -> 712.076 | P8: =ROUND(L8,3) -> 796.799 | Q8: =ROUND(N8,3) -> 881.522 | R8: =K8 -> 2023Q2 | S8: 7974.256 | T8: 4922.4877 | U8: 11026.024 | V8: =ROUND(T8,3) -> 4922.488 | W8: =ROUND(S8,3) -> 7974.256 | X8: =ROUND(U8,3) -> 11026.024
A9: =K8 -> 2023Q2 | B9: =O8 -> 712.076 | C9: =P8 -> 796.799 | D9: =Q8 -> 881.522 | E9: =V8 -> 4922.488 | F9: =W8 -> 7974.256 | G9: =X8 -> 11026.024 | I9: =SUM(F21:F24) -> 35589.901 | K9: 2023Q3 | L9: 800.32012 | M9: 713.29247 | N9: 887.34778 | O9: =ROUND(M9,3) -> 713.292 | P9: =ROUND(L9,3) -> 800.32 | Q9: =ROUND(N9,3) -> 887.348 | R9: =K9 -> 2023Q3 | S9: 7941.5188 | T9: 4600.058 | U9: 11282.98 | V9: =ROUND(T9,3) -> 4600.058 | W9: =ROUND(S9,3) -> 7941.519 | X9: =ROUND(U9,3) -> 11282.98
A10: =K9 -> 2023Q3 | B10: =O9 -> 713.292 | C10: =P9 -> 800.32 | D10: =Q9 -> 887.348 | E10: =V9 -> 4600.058 | F10: =W9 -> 7941.519 | G10: =X9 -> 11282.98 | I10: =SUM(F25:F28) -> 36750.991 | K10: 2023Q4 | L10: 795.77101 | M10: 707.02417 | N10: 884.51784 | O10: =ROUND(M10,3) -> 707.024 | P10: =ROUND(L10,3) -> 795.771 | Q10: =ROUND(N10,3) -> 884.518 | R10: =K10 -> 2023Q4 | S10: 8062.2173 | T10: 4454.14 | U10: 11670.295 | V10: =ROUND(T10,3) -> 4454.14 | W10: =ROUND(S10,3) -> 8062.217 | X10: =ROUND(U10,3) -> 11670.295
A11: =K10 -> 2023Q4 | B11: =O10 -> 707.024 | C11: =P10 -> 795.771 | D11: =Q10 -> 884.518 | E11: =V10 -> 4454.14 | F11: =W10 -> 8062.217 | G11: =X10 -> 11670.295 | I11: =SUM(F29:F32) -> 37912.081 | K11: 2024Q1 | L11: 751.10751 | M11: 661.07037 | N11: 841.14466 | O11: =ROUND(M11,3) -> 661.07 | P11: =ROUND(L11,3) -> 751.108 | Q11: =ROUND(N11,3) -> 841.145 | R11: =K11 -> 2024Q1 | S11: 8128.7373 | T11: 4272.4021 | U11: 11985.072 | V11: =ROUND(T11,3) -> 4272.402 | W11: =ROUND(S11,3) -> 8128.737 | X11: =ROUND(U11,3) -> 11985.072
A12: =K11 -> 2024Q1 | B12: =O11 -> 661.07 | C12: =P11 -> 751.108 | D12: =Q11 -> 841.145 | E12: =V11 -> 4272.402 | F12: =W11 -> 8128.737 | G12: =X11 -> 11985.072 | K12: 2024Q2 | L12: 798.24996 | M12: 707.24012 | N12: 889.2598 | O12: =ROUND(M12,3) -> 707.24 | P12: =ROUND(L12,3) -> 798.25 | Q12: =ROUND(N12,3) -> 889.26 | R12: =K12 -> 2024Q2 | S12: 8264.4603 | T12: 4174.9013 | U12: 12354.019 | V12: =ROUND(T12,3) -> 4174.901 | W12: =ROUND(S12,3) -> 8264.46 | X12: =ROUND(U12,3) -> 12354.019
A13: =K12 -> 2024Q2 | B13: =O12 -> 707.24 | C13: =P12 -> 798.25 | D13: =Q12 -> 889.26 | E13: =V12 -> 4174.901 | F13: =W12 -> 8264.46 | G13: =X12 -> 12354.019 | K13: 2024Q3 | L13: 804.11184 | M13: 712.36639 | N13: 895.85728 | O13: =ROUND(M13,3) -> 712.366 | P13: =ROUND(L13,3) -> 804.112 | Q13: =ROUND(N13,3) -> 895.857 | R13: =K13 -> 2024Q3 | S13: 8231.7707 | T13: 3921.5866 | U13: 12541.955 | V13: =ROUND(T13,3) -> 3921.587 | W13: =ROUND(S13,3) -> 8231.771 | X13: =ROUND(U13,3) -> 12541.955
A14: =K13 -> 2024Q3 | B14: =O13 -> 712.366 | C14: =P13 -> 804.112 | D14: =Q13 -> 895.857 | E14: =V13 -> 3921.587 | F14: =W13 -> 8231.771 | G14: =X13 -> 12541.955 | K14: 2024Q4 | L14: 801.60789 | M14: 709.30483 | N14: 893.91095 | O14: =ROUND(M14,3) -> 709.305 | P14: =ROUND(L14,3) -> 801.608 | Q14: =ROUND(N14,3) -> 893.911 | R14: =K14 -> 2024Q4 | S14: 8352.4835 | T14: 3832.4297 | U14: 12872.537 | V14: =ROUND(T14,3) -> 3832.43 | W14: =ROUND(S14,3) -> 8352.483 | X14: =ROUND(U14,3) -> 12872.537
A15: =K14 -> 2024Q4 | B15: =O14 -> 709.305 | C15: =P14 -> 801.608 | D15: =Q14 -> 893.911 | E15: =V14 -> 3832.43 | F15: =W14 -> 8352.483 | G15: =X14 -> 12872.537 | K15: 2025Q1 | L15: 758.73131 | M15: 666.00484 | N15: 851.45778 | O15: =ROUND(M15,3) -> 666.005 | P15: =ROUND(L15,3) -> 758.731 | Q15: =ROUND(N15,3) -> 851.458 | R15: =K15 -> 2025Q1 | S15: 8419.0078 | T15: 3698.4053 | U15: 13139.61 | V15: =ROUND(T15,3) -> 3698.405 | W15: =ROUND(S15,3) -> 8419.008 | X15: =ROUND(U15,3) -> 13139.61
A16: =K15 -> 2025Q1 | B16: =O15 -> 666.005 | C16: =P15 -> 758.731 | D16: =Q15 -> 851.458 | E16: =V15 -> 3698.405 | F16: =W15 -> 8419.008 | G16: =X15 -> 13139.61 | K16: 2025Q2 | L16: 807.43502 | M16: 714.38662 | N16: 900.48343 | O16: =ROUND(M16,3) -> 714.387 | P16: =ROUND(L16,3) -> 807.435 | Q16: =ROUND(N16,3) -> 900.483 | R16: =K16 -> 2025Q2 | S16: 8554.7322 | T16: 3641.7605 | U16: 13467.704 | V16: =ROUND(T16,3) -> 3641.76 | W16: =ROUND(S16,3) -> 8554.732 | X16: =ROUND(U16,3) -> 13467.704
A17: =K16 -> 2025Q2 | B17: =O16 -> 714.387 | C17: =P16 -> 807.435 | D17: =Q16 -> 900.483 | E17: =V16 -> 3641.76 | F17: =W16 -> 8554.732 | G17: =X16 -> 13467.704 | K17: 2025Q3 | L17: 814.66101 | M17: 721.36759 | N17: 907.95443 | O17: =ROUND(M17,3) -> 721.368 | P17: =ROUND(L17,3) -> 814.661 | Q17: =ROUND(N17,3) -> 907.954 | R17: =K17 -> 2025Q3 | S17: 8522.0429 | T17: 3423.9556 | U17: 13620.13 | V17: =ROUND(T17,3) -> 3423.956 | W17: =ROUND(S17,3) -> 8522.043 | X17: =ROUND(U17,3) -> 13620.13
A18: =K17 -> 2025Q3 | B18: =O17 -> 721.368 | C18: =P17 -> 814.661 | D18: =Q17 -> 907.954 | E18: =V17 -> 3423.956 | F18: =W17 -> 8522.043 | G18: =X17 -> 13620.13 | K18: 2025Q4 | L18: 813.34892 | M18: 719.86889 | N18: 906.82895 | O18: =ROUND(M18,3) -> 719.869 | P18: =ROUND(L18,3) -> 813.349 | Q18: =ROUND(N18,3) -> 906.829 | R18: =K18 -> 2025Q4 | S18: 8642.7559 | T18: 3366.0432 | U18: 13919.469 | V18: =ROUND(T18,3) -> 3366.043 | W18: =ROUND(S18,3) -> 8642.756 | X18: =ROUND(U18,3) -> 13919.469
A19: =K18 -> 2025Q4 | B19: =O18 -> 719.869 | C19: =P18 -> 813.349 | D19: =Q18 -> 906.829 | E19: =V18 -> 3366.043 | F19: =W18 -> 8642.756 | G19: =X18 -> 13919.469 | K19: 2026Q1 | L19: 771.51368 | M19: 677.89145 | N19: 865.13592 | O19: =ROUND(M19,3) -> 677.891 | P19: =ROUND(L19,3) -> 771.514 | Q19: =ROUND(N19,3) -> 865.136 | R19: =K19 -> 2026Q1 | S19: 8709.2802 | T19: 3259.794 | U19: 14158.766 | V19: =ROUND(T19,3) -> 3259.794 | W19: =ROUND(S19,3) -> 8709.28 | X19: =ROUND(U19,3) -> 14158.766
A20: =K19 -> 2026Q1 | B20: =O19 -> 677.891 | C20: =P19 -> 771.514 | D20: =Q19 -> 865.136 | E20: =V19 -> 3259.794 | F20: =W19 -> 8709.28 | G20: =X19 -> 14158.766 | K20: 2026Q2 | L20: 821.12724 | M20: 727.3966 | N20: 914.85789 | O20: =ROUND(M20,3) -> 727.397 | P20: =ROUND(L20,3) -> 821.127 | Q20: =ROUND(N20,3) -> 914.858 | R20: =K20 -> 2026Q2 | S20: 8845.0046 | T20: 3228.0568 | U20: 14461.952 | V20: =ROUND(T20,3) -> 3228.057 | W20: =ROUND(S20,3) -> 8845.005 | X20: =ROUND(U20,3) -> 14461.952
A21: =K20 -> 2026Q2 | B21: =O20 -> 727.397 | C21: =P20 -> 821.127 | D21: =Q20 -> 914.858 | E21: =V20 -> 3228.057 | F21: =W20 -> 8845.005 | G21: =X20 -> 14461.952 | K21: 2026Q3 | L21: 829.14818 | M21: 735.33486 | N21: 922.96151 | O21: =ROUND(M21,3) -> 735.335 | P21: =ROUND(L21,3) -> 829.148 | Q21: =ROUND(N21,3) -> 922.962 | R21: =K21 -> 2026Q3 | S21: 8812.3154 | T21: 3032.756 | U21: 14591.875 | V21: =ROUND(T21,3) -> 3032.756 | W21: =ROUND(S21,3) -> 8812.315 | X21: =ROUND(U21,3) -> 14591.875
A22: =K21 -> 2026Q3 | B22: =O21 -> 735.335 | C22: =P21 -> 829.148 | D22: =Q21 -> 922.962 | E22: =V21 -> 3032.756 | F22: =W21 -> 8812.315 | G22: =X21 -> 14591.875 | K22: 2026Q4 | L22: 828.53066 | M22: 734.65428 | N22: 922.40705 | O22: =ROUND(M22,3) -> 734.654 | P22: =ROUND(L22,3) -> 828.531 | Q22: =ROUND(N22,3) -> 922.407 | R22: =K22 -> 2026Q4 | S22: 8933.0283 | T22: 2995.3092 | U22: 14870.747 | V22: =ROUND(T22,3) -> 2995.309 | W22: =ROUND(S22,3) -> 8933.028 | X22: =ROUND(U22,3) -> 14870.747
A23: =K22 -> 2026Q4 | B23: =O22 -> 734.654 | C23: =P22 -> 828.531 | D23: =Q22 -> 922.407 | E23: =V22 -> 2995.309 | F23: =W22 -> 8933.028 | G23: =X22 -> 14870.747 | K23: 2027Q1 | L23: 787.30229 | M23: 693.37779 | N23: 881.22679 | O23: =ROUND(M23,3) -> 693.378 | P23: =ROUND(L23,3) -> 787.302 | Q23: =ROUND(N23,3) -> 881.227 | R23: =K23 -> 2027Q1 | S23: 8999.5527 | T23: 2907.7786 | U23: 15091.327 | V23: =ROUND(T23,3) -> 2907.779 | W23: =ROUND(S23,3) -> 8999.553 | X23: =ROUND(U23,3) -> 15091.327
... A34: =K33 -> 2029Q3 | B34: =O33 -> 788.88 | C34: =P33 -> 882.949 | D34: =Q33 -> 977.018 | E34: =V33 -> 2223.793 | F34: =W33 -> 9683.133 | G34: =X33 -> 17142.472 | K34: 2029Q4 | L34: 883.10926 | M34: 789.03764 | N34: 977.18088 | O34: =ROUND(M34,3) -> 789.038 | P34: =ROUND(L34,3) -> 883.109 | Q34: =ROUND(N34,3) -> 977.181 | R34: =K34 -> 2029Q4 | S34: 9803.8456 | T34: 2221.3036 | U34: 17386.388 | V34: =ROUND(T34,3) -> 2221.304 | W34: =ROUND(S34,3) -> 9803.846 | X34: =ROUND(U34,3) -> 17386.388
A35: =K34 -> 2029Q4 | B35: =O34 -> 789.038 | C35: =P34 -> 883.109 | D35: =Q34 -> 977.181 | E35: =V34 -> 2221.304 | F35: =W34 -> 9803.846 | G35: =X34 -> 17386.388
A38: Mean | C38: =AVERAGE(C4:C35) -> 815.57872 | F38: =AVERAGE(F4:F35) -> 8680.9957
A41: TDOMCA (Minus 0.5 Standard Deviation) | K41: TDOMCA (Minus 1 Standard Deviation)
B42: ACSS +USBE | E42: LVTS | L42: ACSS +USBE | O42: LVTS
A43: Year | B43: Lower Bound | C43: Forecast Minus Half A Standard Deviation (billions) | D43: Upper Bound | E43: Lower Bound | F43: =C43 -> Forecast Minus Half A Standard Deviation (billions) | G43: Upper Bound | K43: Year | L43: Lower Bound | M43: Forecast Minus One Standard Deviation (billions) | N43: Upper Bound | O43: Lower Bound | P43: =M43 -> Forecast Minus One Standard Deviation (billions) | Q43: Upper Bound
A44: =A4 -> 2022Q1 | C44: =ROUND(C4-((D4-C4)*(0.5/2)),3) -> 756.511 | F44: =ROUND(F4-((G4-F4)*(0.5/2)),3) -> 7372.252 | K44: =A4 -> 2022Q1 | M44: =ROUND(C4-((D4-C4)*(1/2)),3) -> 744.269 | P44: =ROUND(F4-((G4-F4)*(1/2)),3) -> 7168.96
A45: =A5 -> 2022Q2 | C45: =ROUND(C5-((D5-C5)*(0.5/2)),3) -> 792.958 | F45: =ROUND(F5-((G5-F5)*(0.5/2)),3) -> 7330.658 | K45: =A5 -> 2022Q2 | M45: =ROUND(C5-((D5-C5)*(1/2)),3) -> 777.297 | P45: =ROUND(F5-((G5-F5)*(1/2)),3) -> 6969.139
A46: =A6 -> 2022Q3 | C46: =ROUND(C6-((D6-C6)*(0.5/2)),3) -> 790.287 | F46: =ROUND(F6-((G6-F6)*(0.5/2)),3) -> 7165.695 | K46: =A6 -> 2022Q3 | M46: =ROUND(C6-((D6-C6)*(1/2)),3) -> 772.451 | P46: =ROUND(F6-((G6-F6)*(1/2)),3) -> 6677.67
A47: =A7 -> 2022Q4 | C47: =ROUND(C7-((D7-C7)*(0.5/2)),3) -> 780.732 | F47: =ROUND(F7-((G7-F7)*(0.5/2)),3) -> 7179.869 | K47: =A7 -> 2022Q4 | M47: =ROUND(C7-((D7-C7)*(1/2)),3) -> 761.399 | P47: =ROUND(F7-((G7-F7)*(1/2)),3) -> 6587.046
A48: =A8 -> 2023Q1 | C48: =ROUND(C8-((D8-C8)*(0.5/2)),3) -> 731.935 | F48: =ROUND(F8-((G8-F8)*(0.5/2)),3) -> 7155.691 | K48: =A8 -> 2023Q1 | M48: =ROUND(C8-((D8-C8)*(1/2)),3) -> 711.534 | P48: =ROUND(F8-((G8-F8)*(1/2)),3) -> 6472.691
A49: =A9 -> 2023Q2 | C49: =ROUND(C9-((D9-C9)*(0.5/2)),3) -> 775.618 | F49: =ROUND(F9-((G9-F9)*(0.5/2)),3) -> 7211.314 | K49: =A9 -> 2023Q2 | M49: =ROUND(C9-((D9-C9)*(1/2)),3) -> 754.438 | P49: =ROUND(F9-((G9-F9)*(1/2)),3) -> 6448.372
A50: =A10 -> 2023Q3 | C50: =ROUND(C10-((D10-C10)*(0.5/2)),3) -> 778.563 | F50: =ROUND(F10-((G10-F10)*(0.5/2)),3) -> 7106.154 | K50: =A10 -> 2023Q3 | M50: =ROUND(C10-((D10-C10)*(1/2)),3) -> 756.806 | P50: =ROUND(F10-((G10-F10)*(1/2)),3) -> 6270.789
A51: =A11 -> 2023Q4 | C51: =ROUND(C11-((D11-C11)*(0.5/2)),3) -> 773.584 | F51: =ROUND(F11-((G11-F11)*(0.5/2)),3) -> 7160.198 | K51: =A11 -> 2023Q4 | M51: =ROUND(C11-((D11-C11)*(1/2)),3) -> 751.398 | P51: =ROUND(F11-((G11-F11)*(1/2)),3) -> 6258.178
A52: =A12 -> 2024Q1 | C52: =ROUND(C12-((D12-C12)*(0.5/2)),3) -> 728.599 | F52: =ROUND(F12-((G12-F12)*(0.5/2)),3) -> 7164.653 | K52: =A12 -> 2024Q1 | M52: =ROUND(C12-((D12-C12)*(1/2)),3) -> 706.09 | P52: =ROUND(F12-((G12-F12)*(1/2)),3) -> 6200.57
A53: =A13 -> 2024Q2 | C53: =ROUND(C13-((D13-C13)*(0.5/2)),3) -> 775.498 | F53: =ROUND(F13-((G13-F13)*(0.5/2)),3) -> 7242.07 | K53: =A13 -> 2024Q2 | M53: =ROUND(C13-((D13-C13)*(1/2)),3) -> 752.745 | P53: =ROUND(F13-((G13-F13)*(1/2)),3) -> 6219.681
A54: =A14 -> 2024Q3 | C54: =ROUND(C14-((D14-C14)*(0.5/2)),3) -> 781.176 | F54: =ROUND(F14-((G14-F14)*(0.5/2)),3) -> 7154.225 | K54: =A14 -> 2024Q3 | M54: =ROUND(C14-((D14-C14)*(1/2)),3) -> 758.24 | P54: =ROUND(F14-((G14-F14)*(1/2)),3) -> 6076.679
...

Sheet NOSCCA
A1: NOSCCA | L1: ACSS | S1: LVTS
B2: ACSS +USBE | E2: LVTS | L2: Point Forecast | M2: Lo 95 | N2: Hi 95 | O2: Lo 95 | P2: Point Forecast | Q2: Hi 95 | S2: Point Forecast | T2: Lo 95 | U2: Hi 95 | V2: Lo 95 | W2: Point Forecast | X2: Hi 95
A3: Year | B3: Lower Bound | C3: Value Forecast (billions) | D3: Upper Bound | E3: Lower Bound | F3: Value Forecast (billions) | G3: Upper Bound | K3: 2022Q1 | L3: 507.33287 | M3: 475.38911 | N3: 539.27662 | O3: =ROUND(M3,3) -> 475.389 | P3: =ROUND(L3,3) -> 507.333 | Q3: =ROUND(N3,3) -> 539.277 | R3: =K3 -> 2022Q1 | S3: 2491.9282 | T3: 2047.266 | U3: 2936.5904 | V3: =ROUND(T3,3) -> 2047.266 | W3: =ROUND(S3,3) -> 2491.928 | X3: =ROUND(U3,3) -> 2936.59
A4: =K3 -> 2022Q1 | B4: =O3 -> 475.389 | C4: =P3 -> 507.333 | D4: =Q3 -> 539.277 | E4: =V3 -> 2047.266 | F4: =W3 -> 2491.928 | G4: =X3 -> 2936.59 | K4: 2022Q2 | L4: 535.60114 | M4: 495.00347 | N4: 576.19881 | O4: =ROUND(M4,3) -> 495.003 | P4: =ROUND(L4,3) -> 535.601 | Q4: =ROUND(N4,3) -> 576.199 | R4: =K4 -> 2022Q2 | S4: 2569.4068 | T4: 2053.8891 | U4: 3084.9244 | V4: =ROUND(T4,3) -> 2053.889 | W4: =ROUND(S4,3) -> 2569.407 | X4: =ROUND(U4,3) -> 3084.924
A5: =K4 -> 2022Q2 | B5: =O4 -> 495.003 | C5: =P4 -> 535.601 | D5: =Q4 -> 576.199 | E5: =V4 -> 2053.889 | F5: =W4 -> 2569.407 | G5: =X4 -> 3084.924 | I5: =SUM(F5:F8) -> 10223.24 | K5: 2022Q3 | L5: 536.399 | M5: 489.70605 | N5: 583.09195 | O5: =ROUND(M5,3) -> 489.706 | P5: =ROUND(L5,3) -> 536.399 | Q5: =ROUND(N5,3) -> 583.092 | R5: =K5 -> 2022Q3 | S5: 2548.73 | T5: 1966.9296 | U5: 3130.5304 | V5: =ROUND(T5,3) -> 1966.93 | W5: =ROUND(S5,3) -> 2548.73 | X5: =ROUND(U5,3) -> 3130.53
A6: =K5 -> 2022Q3 | B6: =O5 -> 489.706 | C6: =P5 -> 536.399 | D6: =Q5 -> 583.092 | E6: =V5 -> 1966.93 | F6: =W5 -> 2548.73 | G6: =X5 -> 3130.53 | I6: =SUM(F9:F12) -> 10483.18 | K6: 2022Q4 | L6: 531.1201 | M6: 479.82512 | N6: 582.41509 | O6: =ROUND(M6,3) -> 479.825 | P6: =ROUND(L6,3) -> 531.12 | Q6: =ROUND(N6,3) -> 582.415 | R6: =K6 -> 2022Q4 | S6: 2553.0964 | T6: 1912.0075 | U6: 3194.1853 | V6: =ROUND(T6,3) -> 1912.008 | W6: =ROUND(S6,3) -> 2553.096 | X6: =ROUND(U6,3) -> 3194.185
A7: =K6 -> 2022Q4 | B7: =O6 -> 479.825 | C7: =P6 -> 531.12 | D7: =Q6 -> 582.415 | E7: =V6 -> 1912.008 | F7: =W6 -> 2553.096 | G7: =X6 -> 3194.185 | I7: =SUM(F13:F16) -> 10742.899 | K7: 2023Q1 | L7: 502.92331 | M7: 448.02913 | N7: 557.81749 | O7: =ROUND(M7,3) -> 448.029 | P7: =ROUND(L7,3) -> 502.923 | Q7: =ROUND(N7,3) -> 557.817 | R7: =K7 -> 2023Q1 | S7: 2552.0071 | T7: 1856.6588 | U7: 3247.3554 | V7: =ROUND(T7,3) -> 1856.659 | W7: =ROUND(S7,3) -> 2552.007 | X7: =ROUND(U7,3) -> 3247.355
A8: =K7 -> 2023Q1 | B8: =O7 -> 448.029 | C8: =P7 -> 502.923 | D8: =Q7 -> 557.817 | E8: =V7 -> 1856.659 | F8: =W7 -> 2552.007 | G8: =X7 -> 3247.355 | I8: =SUM(F17:F20) -> 11002.616 | K8: 2023Q2 | L8: 532.44587 | M8: 474.67652 | N8: 590.21522 | O8: =ROUND(M8,3) -> 474.677 | P8: =ROUND(L8,3) -> 532.446 | Q8: =ROUND(N8,3) -> 590.215 | R8: =K8 -> 2023Q2 | S8: 2634.5699 | T8: 1888.9003 | U8: 3380.2394 | V8: =ROUND(T8,3) -> 1888.9 | W8: =ROUND(S8,3) -> 2634.57 | X8: =ROUND(U8,3) -> 3380.239
A9: =K8 -> 2023Q2 | B9: =O8 -> 474.677 | C9: =P8 -> 532.446 | D9: =Q8 -> 590.215 | E9: =V8 -> 1888.9 | F9: =W8 -> 2634.57 | G9: =X8 -> 3380.239 | I9: =SUM(F21:F24) -> 11262.334 | K9: 2023Q3 | L9: 534.39845 | M9: 474.29987 | N9: 594.49704 | O9: =ROUND(M9,3) -> 474.3 | P9: =ROUND(L9,3) -> 534.398 | Q9: =ROUND(N9,3) -> 594.497 | R9: =K9 -> 2023Q3 | S9: 2613.6482 | T9: 1820.845 | U9: 3406.4514 | V9: =ROUND(T9,3) -> 1820.845 | W9: =ROUND(S9,3) -> 2613.648 | X9: =ROUND(U9,3) -> 3406.451
A10: =K9 -> 2023Q3 | B10: =O9 -> 474.3 | C10: =P9 -> 534.398 | D10: =Q9 -> 594.497 | E10: =V9 -> 1820.845 | F10: =W9 -> 2613.648 | G10: =X9 -> 3406.451 | I10: =SUM(F25:F28) -> 11522.051 | K10: 2023Q4 | L10: 530.18262 | M10: 468.17837 | N10: 592.18686 | O10: =ROUND(M10,3) -> 468.178 | P10: =ROUND(L10,3) -> 530.183 | Q10: =ROUND(N10,3) -> 592.187 | R10: =K10 -> 2023Q4 | S10: 2618.0263 | T10: 1780.7386 | U10: 3455.314 | V10: =ROUND(T10,3) -> 1780.739 | W10: =ROUND(S10,3) -> 2618.026 | X10: =ROUND(U10,3) -> 3455.314
A11: =K10 -> 2023Q4 | B11: =O10 -> 468.178 | C11: =P10 -> 530.183 | D11: =Q10 -> 592.187 | E11: =V10 -> 1780.739 | F11: =W10 -> 2618.026 | G11: =X10 -> 3455.314 | I11: =SUM(F29:F32) -> 11781.768 | K11: 2024Q1 | L11: 502.9645 | M11: 439.38983 | N11: 566.53917 | O11: =ROUND(M11,3) -> 439.39 | P11: =ROUND(L11,3) -> 502.965 | Q11: =ROUND(N11,3) -> 566.539 | R11: =K11 -> 2024Q1 | S11: 2616.9364 | T11: 1737.4113 | U11: 3496.4616 | V11: =ROUND(T11,3) -> 1737.411 | W11: =ROUND(S11,3) -> 2616.936 | X11: =ROUND(U11,3) -> 3496.462
A12: =K11 -> 2024Q1 | B12: =O11 -> 439.39 | C12: =P11 -> 502.965 | D12: =Q11 -> 566.539 | E12: =V11 -> 1737.411 | F12: =W11 -> 2616.936 | G12: =X11 -> 3496.462 | K12: 2024Q2 | L12: 533.38805 | M12: 468.51214 | N12: 598.26397 | O12: =ROUND(M12,3) -> 468.512 | P12: =ROUND(L12,3) -> 533.388 | Q12: =ROUND(N12,3) -> 598.264 | R12: =K12 -> 2024Q2 | S12: 2699.4993 | T12: 1779.6741 | U12: 3619.3244 | V12: =ROUND(T12,3) -> 1779.674 | W12: =ROUND(S12,3) -> 2699.499 | X12: =ROUND(U12,3) -> 3619.324
A13: =K12 -> 2024Q2 | B13: =O12 -> 468.512 | C13: =P12 -> 533.388 | D13: =Q12 -> 598.264 | E13: =V12 -> 1779.674 | F13: =W12 -> 2699.499 | G13: =X12 -> 3619.324 | K13: 2024Q3 | L13: 536.17011 | M13: 470.21142 | N13: 602.12879 | O13: =ROUND(M13,3) -> 470.211 | P13: =ROUND(L13,3) -> 536.17 | Q13: =ROUND(N13,3) -> 602.129 | R13: =K13 -> 2024Q3 | S13: 2678.5776 | T13: 1720.1455 | U13: 3637.0097 | V13: =ROUND(T13,3) -> 1720.145 | W13: =ROUND(S13,3) -> 2678.578 | X13: =ROUND(U13,3) -> 3637.01
A14: =K13 -> 2024Q3 | B14: =O13 -> 470.211 | C14: =P13 -> 536.17 | D14: =Q13 -> 602.129 | E14: =V13 -> 1720.145 | F14: =W13 -> 2678.578 | G14: =X13 -> 3637.01 | K14: 2024Q4 | L14: 532.7179 | M14: 465.85525 | N14: 599.58055 | O14: =ROUND(M14,3) -> 465.855 | P14: =ROUND(L14,3) -> 532.718 | Q14: =ROUND(N14,3) -> 599.581 | R14: =K14 -> 2024Q4 | S14: 2682.9557 | T14: 1687.4127 | U14: 3678.4988 | V14: =ROUND(T14,3) -> 1687.413 | W14: =ROUND(S14,3) -> 2682.956 | X14: =ROUND(U14,3) -> 3678.499
A15: =K14 -> 2024Q4 | B15: =O14 -> 465.855 | C15: =P14 -> 532.718 | D15: =Q14 -> 599.581 | E15: =V14 -> 1687.413 | F15: =W14 -> 2682.956 | G15: =X14 -> 3678.499 | K15: 2025Q1 | L15: 506.2028 | M15: 438.58346 | N15: 573.82214 | O15: =ROUND(M15,3) -> 438.583 | P15: =ROUND(L15,3) -> 506.203 | Q15: =ROUND(N15,3) -> 573.822 | R15: =K15 -> 2025Q1 | S15: 2681.8658 | T15: 1650.5464 | U15: 3713.1853 | V15: =ROUND(T15,3) -> 1650.546 | W15: =ROUND(S15,3) -> 2681.866 | X15: =ROUND(U15,3) -> 3713.185
A16: =K15 -> 2025Q1 | B16: =O15 -> 438.583 | C16: =P15 -> 506.203 | D16: =Q15 -> 573.822 | E16: =V15 -> 1650.546 | F16: =W15 -> 2681.866 | G16: =X15 -> 3713.185 | K16: 2025Q2 | L16: 537.27356 | M16: 469.01946 | N16: 605.52766 | O16: =ROUND(M16,3) -> 469.019 | P16: =ROUND(L16,3) -> 537.274 | Q16: =ROUND(N16,3) -> 605.528 | R16: =K16 -> 2025Q2 | S16: 2764.4287 | T16: 1698.533 | U16: 3830.3244 | V16: =ROUND(T16,3) -> 1698.533 | W16: =ROUND(S16,3) -> 2764.429 | X16: =ROUND(U16,3) -> 3830.324
A17: =K16 -> 2025Q2 | B17: =O16 -> 469.019 | C17: =P16 -> 537.274 | D17: =Q16 -> 605.528 | E17: =V16 -> 1698.533 | F17: =W16 -> 2764.429 | G17: =X16 -> 3830.324 | K17: 2025Q3 | L17: 540.65145 | M17: 471.86395 | N17: 609.43895 | O17: =ROUND(M17,3) -> 471.864 | P17: =ROUND(L17,3) -> 540.651 | Q17: =ROUND(N17,3) -> 609.439 | R17: =K17 -> 2025Q3 | S17: 2743.507 | T17: 1644.122 | U17: 3842.892 | V17: =ROUND(T17,3) -> 1644.122 | W17: =ROUND(S17,3) -> 2743.507 | X17: =ROUND(U17,3) -> 3842.892
A18: =K17 -> 2025Q3 | B18: =O17 -> 471.864 | C18: =P17 -> 540.651 | D18: =Q17 -> 609.439 | E18: =V17 -> 1644.122 | F18: =W17 -> 2743.507 | G18: =X17 -> 3842.892 | K18: 2025Q4 | L18: 537.74778 | M18: 468.51142 | N18: 606.98415 | O18: =ROUND(M18,3) -> 468.511 | P18: =ROUND(L18,3) -> 537.748 | Q18: =ROUND(N18,3) -> 606.984 | R18: =K18 -> 2025Q4 | S18: 2747.8851 | T18: 1616.0012 | U18: 3879.7691 | V18: =ROUND(T18,3) -> 1616.001 | W18: =ROUND(S18,3) -> 2747.885 | X18: =ROUND(U18,3) -> 3879.769
A19: =K18 -> 2025Q4 | B19: =O18 -> 468.511 | C19: =P18 -> 537.748 | D19: =Q18 -> 606.984 | E19: =V18 -> 1616.001 | F19: =W18 -> 2747.885 | G19: =X18 -> 3879.769 | K19: 2026Q1 | L19: 511.73768 | M19: 442.12315 | N19: 581.35221 | O19: =ROUND(M19,3) -> 442.123 | P19: =ROUND(L19,3) -> 511.738 | Q19: =ROUND(N19,3) -> 581.352 | R19: =K19 -> 2026Q1 | S19: 2746.7952 | T19: 1583.3198 | U19: 3910.2707 | V19: =ROUND(T19,3) -> 1583.32 | W19: =ROUND(S19,3) -> 2746.795 | X19: =ROUND(U19,3) -> 3910.271
A20: =K19 -> 2026Q1 | B20: =O19 -> 442.123 | C20: =P19 -> 511.738 | D20: =Q19 -> 581.352 | E20: =V19 -> 1583.32 | F20: =W19 -> 2746.795 | G20: =X19 -> 3910.271 | K20: 2026Q2 | L20: 543.27335 | M20: 473.33991 | N20: 613.20679 | O20: =ROUND(M20,3) -> 473.34 | P20: =ROUND(L20,3) -> 543.273 | Q20: =ROUND(N20,3) -> 613.207 | R20: =K20 -> 2026Q2 | S20: 2829.3581 | T20: 1635.1266 | U20: 4023.5896 | V20: =ROUND(T20,3) -> 1635.127 | W20: =ROUND(S20,3) -> 2829.358 | X20: =ROUND(U20,3) -> 4023.59
A21: =K20 -> 2026Q2 | B21: =O20 -> 473.34 | C21: =P20 -> 543.273 | D21: =Q20 -> 613.207 | E21: =V20 -> 1635.127 | F21: =W20 -> 2829.358 | G21: =X20 -> 4023.59 | K21: 2026Q3 | L21: 547.07924 | M21: 476.87665 | N21: 617.28184 | O21: =ROUND(M21,3) -> 476.877 | P21: =ROUND(L21,3) -> 547.079 | Q21: =ROUND(N21,3) -> 617.282 | R21: =K21 -> 2026Q3 | S21: 2808.4364 | T21: 1584.2213 | U21: 4032.6515 | V21: =ROUND(T21,3) -> 1584.221 | W21: =ROUND(S21,3) -> 2808.436 | X21: =ROUND(U21,3) -> 4032.651
A22: =K21 -> 2026Q3 | B22: =O21 -> 476.877 | C22: =P21 -> 547.079 | D22: =Q21 -> 617.282 | E22: =V21 -> 1584.221 | F22: =W21 -> 2808.436 | G22: =X21 -> 4032.651 | K22: 2026Q4 | L22: 544.56961 | M22: 474.1397 | N22: 614.99952 | O22: =ROUND(M22,3) -> 474.14 | P22: =ROUND(L22,3) -> 544.57 | Q22: =ROUND(N22,3) -> 615 | R22: =K22 -> 2026Q4 | S22: 2812.8145 | T22: 1559.3328 | U22: 4066.2963 | V22: =ROUND(T22,3) -> 1559.333 | W22: =ROUND(S22,3) -> 2812.815 | X22: =ROUND(U22,3) -> 4066.296
A23: =K22 -> 2026Q4 | B23: =O22 -> 474.14 | C23: =P22 -> 544.57 | D23: =Q22 -> 615 | E23: =V22 -> 1559.333 | F23: =W22 -> 2812.815 | G23: =X22 -> 4066.296 | K23: 2027Q1 | L23: 518.92226 | M23: 448.30026 | N23: 589.54426 | O23: =ROUND(M23,3) -> 448.3 | P23: =ROUND(L23,3) -> 518.922 | Q23: =ROUND(N23,3) -> 589.544 | R23: =K23 -> 2027Q1 | S23: 2811.7246 | T23: 1529.6442 | U23: 4093.8051 | V23: =ROUND(T23,3) -> 1529.644 | W23: =ROUND(S23,3) -> 2811.725 | X23: =ROUND(U23,3) -> 4093.805
... A34: =K33 -> 2029Q3 | B34: =O33 -> 501.808 | C34: =P33 -> 573.287 | D34: =Q33 -> 644.767 | E34: =V33 -> 1464.112 | F34: =W33 -> 3003.225 | G34: =X33 -> 4542.337 | K34: 2029Q4 | L34: 571.41019 | M34: 499.90022 | N34: 642.92015 | O34: =ROUND(M34,3) -> 499.9 | P34: =ROUND(L34,3) -> 571.41 | Q34: =ROUND(N34,3) -> 642.92 | R34: =K34 -> 2029Q4 | S34: 3007.6027 | T34: 1445.1104 | U34: 4570.0951 | V34: =ROUND(T34,3) -> 1445.11 | W34: =ROUND(S34,3) -> 3007.603 | X34: =ROUND(U34,3) -> 4570.095
A35: =K34 -> 2029Q4 | B35: =O34 -> 499.9 | C35: =P34 -> 571.41 | D35: =Q34 -> 642.92 | E35: =V34 -> 1445.11 | F35: =W34 -> 3007.603 | G35: =X34 -> 4570.095
A38: Mean | C38: =AVERAGE(C4:C35) -> 538.23825 | F38: =AVERAGE(F4:F35) -> 2767.0309
A41: NOSCCA (Minus 0.5 Standard Deviation) | K41: NOSCCA (Minus 1 Standard Deviation)
B42: ACSS +USBE | E42: LVTS | L42: ACSS +USBE | O42: LVTS
A43: Year | B43: Lower Bound | C43: Forecast Minus Half A Standard Deviation (billions) | D43: Upper Bound | E43: Lower Bound | F43: =C43 -> Forecast Minus Half A Standard Deviation (billions) | G43: Upper Bound | K43: Year | L43: Lower Bound | M43: Forecast Minus One Standard Deviation (billions) | N43: Upper Bound | O43: Lower Bound | P43: =M43 -> Forecast Minus One Standard Deviation (billions) | Q43: Upper Bound
A44: =A4 -> 2022Q1 | C44: =ROUND(C4-((D4-C4)*(0.5/2)),3) -> 499.347 | F44: =ROUND(F4-((G4-F4)*(0.5/2)),3) -> 2380.763 | K44: =A4 -> 2022Q1 | M44: =ROUND(C4-((D4-C4)*(1/2)),3) -> 491.361 | P44: =ROUND(F4-((G4-F4)*(1/2)),3) -> 2269.597
A45: =A5 -> 2022Q2 | C45: =ROUND(C5-((D5-C5)*(0.5/2)),3) -> 525.452 | F45: =ROUND(F5-((G5-F5)*(0.5/2)),3) -> 2440.528 | K45: =A5 -> 2022Q2 | M45: =ROUND(C5-((D5-C5)*(1/2)),3) -> 515.302 | P45: =ROUND(F5-((G5-F5)*(1/2)),3) -> 2311.649
A46: =A6 -> 2022Q3 | C46: =ROUND(C6-((D6-C6)*(0.5/2)),3) -> 524.726 | F46: =ROUND(F6-((G6-F6)*(0.5/2)),3) -> 2403.28 | K46: =A6 -> 2022Q3 | M46: =ROUND(C6-((D6-C6)*(1/2)),3) -> 513.053 | P46: =ROUND(F6-((G6-F6)*(1/2)),3) -> 2257.83
A47: =A7 -> 2022Q4 | C47: =ROUND(C7-((D7-C7)*(0.5/2)),3) -> 518.296 | F47: =ROUND(F7-((G7-F7)*(0.5/2)),3) -> 2392.824 | K47: =A7 -> 2022Q4 | M47: =ROUND(C7-((D7-C7)*(1/2)),3) -> 505.473 | P47: =ROUND(F7-((G7-F7)*(1/2)),3) -> 2232.552
A48: =A8 -> 2023Q1 | C48: =ROUND(C8-((D8-C8)*(0.5/2)),3) -> 489.2 | F48: =ROUND(F8-((G8-F8)*(0.5/2)),3) -> 2378.17 | K48: =A8 -> 2023Q1 | M48: =ROUND(C8-((D8-C8)*(1/2)),3) -> 475.476 | P48: =ROUND(F8-((G8-F8)*(1/2)),3) -> 2204.333
A49: =A9 -> 2023Q2 | C49: =ROUND(C9-((D9-C9)*(0.5/2)),3) -> 518.004 | F49: =ROUND(F9-((G9-F9)*(0.5/2)),3) -> 2448.153 | K49: =A9 -> 2023Q2 | M49: =ROUND(C9-((D9-C9)*(1/2)),3) -> 503.562 | P49: =ROUND(F9-((G9-F9)*(1/2)),3) -> 2261.736
A50: =A10 -> 2023Q3 | C50: =ROUND(C10-((D10-C10)*(0.5/2)),3) -> 519.373 | F50: =ROUND(F10-((G10-F10)*(0.5/2)),3) -> 2415.447 | K50: =A10 -> 2023Q3 | M50: =ROUND(C10-((D10-C10)*(1/2)),3) -> 504.349 | P50: =ROUND(F10-((G10-F10)*(1/2)),3) -> 2217.247
A51: =A11 -> 2023Q4 | C51: =ROUND(C11-((D11-C11)*(0.5/2)),3) -> 514.682 | F51: =ROUND(F11-((G11-F11)*(0.5/2)),3) -> 2408.704 | K51: =A11 -> 2023Q4 | M51: =ROUND(C11-((D11-C11)*(1/2)),3) -> 499.181 | P51: =ROUND(F11-((G11-F11)*(1/2)),3) -> 2199.382
A52: =A12 -> 2024Q1 | C52: =ROUND(C12-((D12-C12)*(0.5/2)),3) -> 487.072 | F52: =ROUND(F12-((G12-F12)*(0.5/2)),3) -> 2397.055 | K52: =A12 -> 2024Q1 | M52: =ROUND(C12-((D12-C12)*(1/2)),3) -> 471.178 | P52: =ROUND(F12-((G12-F12)*(1/2)),3) -> 2177.173
A53: =A13 -> 2024Q2 | C53: =ROUND(C13-((D13-C13)*(0.5/2)),3) -> 517.169 | F53: =ROUND(F13-((G13-F13)*(0.5/2)),3) -> 2469.543 | K53: =A13 -> 2024Q2 | M53: =ROUND(C13-((D13-C13)*(1/2)),3) -> 500.95 | P53: =ROUND(F13-((G13-F13)*(1/2)),3) -> 2239.587
A54: =A14 -> 2024Q3 | C54: =ROUND(C14-((D14-C14)*(0.5/2)),3) -> 519.68 | F54: =ROUND(F14-((G14-F14)*(0.5/2)),3) -> 2438.97 | K54: =A14 -> 2024Q3 | M54: =ROUND(C14-((D14-C14)*(1/2)),3) -> 503.191 | P54: =ROUND(F14-((G14-F14)*(1/2)),3) -> 2199.362
...

Sheet CIBCCA
A1: CIBCCA | L1: ACSS | S1: LVTS
B2: ACSS +USBE | E2: LVTS | L2: Point Forecast | M2: Lo 95 | N2: Hi 95 | O2: Lo 95 | P2: Point Forecast | Q2: Hi 95 | S2: Point Forecast | T2: Lo 95 | U2: Hi 95 | V2: Lo 95 | W2: Point Forecast | X2: Hi 95
A3: Year | B3: Lower Bound | C3: Value Forecast (billions) | D3: Upper Bound | E3: Lower Bound | F3: Value Forecast (billions) | G3: Upper Bound | K3: 2022Q1 | L3: 528.33309 | M3: 496.63226 | N3: 560.03392 | O3: =ROUND(M3,3) -> 496.632 | P3: =ROUND(L3,3) -> 528.333 | Q3: =ROUND(N3,3) -> 560.034 | R3: =K3 -> 2022Q1 | S3: 5590.671 | T3: 4966.1479 | U3: 6215.1941 | V3: =ROUND(T3,3) -> 4966.148 | W3: =ROUND(S3,3) -> 5590.671 | X3: =ROUND(U3,3) -> 6215.194
A4: =K3 -> 2022Q1 | B4: =O3 -> 496.632 | C4: =P3 -> 528.333 | D4: =Q3 -> 560.034 | E4: =V3 -> 4966.148 | F4: =W3 -> 5590.671 | G4: =X3 -> 6215.194 | K4: 2022Q2 | L4: 560.79552 | M4: 514.85851 | N4: 606.73252 | O4: =ROUND(M4,3) -> 514.859 | P4: =ROUND(L4,3) -> 560.796 | Q4: =ROUND(N4,3) -> 606.733 | R4: =K4 -> 2022Q2 | S4: 5749.5821 | T4: 4811.1846 | U4: 6687.9796 | V4: =ROUND(T4,3) -> 4811.185 | W4: =ROUND(S4,3) -> 5749.582 | X4: =ROUND(U4,3) -> 6687.98
A5: =K4 -> 2022Q2 | B5: =O4 -> 514.859 | C5: =P4 -> 560.796 | D5: =Q4 -> 606.733 | E5: =V4 -> 4811.185 | F5: =W4 -> 5749.582 | G5: =X4 -> 6687.98 | I5: =SUM(F5:F8) -> 22865.195 | K5: 2022Q3 | L5: 561.0799 | M5: 505.35341 | N5: 616.80639 | O5: =ROUND(M5,3) -> 505.353 | P5: =ROUND(L5,3) -> 561.08 | Q5: =ROUND(N5,3) -> 616.806 | R5: =K5 -> 2022Q3 | S5: 5715.2902 | T5: 4530.3106 | U5: 6900.2697 | V5: =ROUND(T5,3) -> 4530.311 | W5: =ROUND(S5,3) -> 5715.29 | X5: =ROUND(U5,3) -> 6900.27
A6: =K5 -> 2022Q3 | B6: =O5 -> 505.353 | C6: =P5 -> 561.08 | D6: =Q5 -> 616.806 | E6: =V5 -> 4530.311 | F6: =W5 -> 5715.29 | G6: =X5 -> 6900.27 | I6: =SUM(F9:F12) -> 23428.915 | K6: 2022Q4 | L6: 561.66752 | M6: 498.40935 | N6: 624.92569 | O6: =ROUND(M6,3) -> 498.409 | P6: =ROUND(L6,3) -> 561.668 | Q6: =ROUND(N6,3) -> 624.926 | R6: =K6 -> 2022Q4 | S6: 5676.5863 | T6: 4284.4395 | U6: 7068.7331 | V6: =ROUND(T6,3) -> 4284.44 | W6: =ROUND(S6,3) -> 5676.586 | X6: =ROUND(U6,3) -> 7068.733
A7: =K6 -> 2022Q4 | B7: =O6 -> 498.409 | C7: =P6 -> 561.668 | D7: =Q6 -> 624.926 | E7: =V6 -> 4284.44 | F7: =W6 -> 5676.586 | G7: =X6 -> 7068.733 | I7: =SUM(F13:F16) -> 23996.453 | K7: 2023Q1 | L7: 522.92842 | M7: 453.58482 | N7: 592.27203 | O7: =ROUND(M7,3) -> 453.585 | P7: =ROUND(L7,3) -> 522.928 | Q7: =ROUND(N7,3) -> 592.272 | R7: =K7 -> 2023Q1 | S7: 5723.7371 | T7: 4150.4793 | U7: 7296.9948 | V7: =ROUND(T7,3) -> 4150.479 | W7: =ROUND(S7,3) -> 5723.737 | X7: =ROUND(U7,3) -> 7296.995
A8: =K7 -> 2023Q1 | B8: =O7 -> 453.585 | C8: =P7 -> 522.928 | D8: =Q7 -> 592.272 | E8: =V7 -> 4150.479 | F8: =W7 -> 5723.737 | G8: =X7 -> 7296.995 | I8: =SUM(F17:F20) -> 24564.024 | K8: 2023Q2 | L8: 555.97549 | M8: 481.57695 | N8: 630.37402 | O8: =ROUND(M8,3) -> 481.577 | P8: =ROUND(L8,3) -> 555.975 | Q8: =ROUND(N8,3) -> 630.374 | R8: =K8 -> 2023Q2 | S8: 5888.7769 | T8: 4152.926 | U8: 7624.6278 | V8: =ROUND(T8,3) -> 4152.926 | W8: =ROUND(S8,3) -> 5888.777 | X8: =ROUND(U8,3) -> 7624.628
A9: =K8 -> 2023Q2 | B9: =O8 -> 481.577 | C9: =P8 -> 555.975 | D9: =Q8 -> 630.374 | E9: =V8 -> 4152.926 | F9: =W8 -> 5888.777 | G9: =X8 -> 7624.628 | I9: =SUM(F21:F24) -> 25131.593 | K9: 2023Q3 | L9: 556.81464 | M9: 478.14182 | N9: 635.48746 | O9: =ROUND(M9,3) -> 478.142 | P9: =ROUND(L9,3) -> 556.815 | Q9: =ROUND(N9,3) -> 635.487 | R9: =K9 -> 2023Q3 | S9: 5856.3583 | T9: 3971.8122 | U9: 7740.9043 | V9: =ROUND(T9,3) -> 3971.812 | W9: =ROUND(S9,3) -> 5856.358 | X9: =ROUND(U9,3) -> 7740.904
A10: =K9 -> 2023Q3 | B10: =O9 -> 478.142 | C10: =P9 -> 556.815 | D10: =Q9 -> 635.487 | E10: =V9 -> 3971.812 | F10: =W9 -> 5856.358 | G10: =X9 -> 7740.904 | I10: =SUM(F25:F28) -> 25699.165 | K10: 2023Q4 | L10: 557.9287 | M10: 475.59676 | N10: 640.26063 | O10: =ROUND(M10,3) -> 475.597 | P10: =ROUND(L10,3) -> 557.929 | Q10: =ROUND(N10,3) -> 640.261 | R10: =K10 -> 2023Q4 | S10: 5818.227 | T10: 3795.867 | U10: 7840.5871 | V10: =ROUND(T10,3) -> 3795.867 | W10: =ROUND(S10,3) -> 5818.227 | X10: =ROUND(U10,3) -> 7840.587
A11: =K10 -> 2023Q4 | B11: =O10 -> 475.597 | C11: =P10 -> 557.929 | D11: =Q10 -> 640.261 | E11: =V10 -> 3795.867 | F11: =W10 -> 5818.227 | G11: =X10 -> 7840.587 | I11: =SUM(F29:F32) -> 26266.737 | K11: 2024Q1 | L11: 519.68914 | M11: 434.19626 | N11: 605.18203 | O11: =ROUND(M11,3) -> 434.196 | P11: =ROUND(L11,3) -> 519.689 | Q11: =ROUND(N11,3) -> 605.182 | R11: =K11 -> 2024Q1 | S11: 5865.5528 | T11: 3714.1825 | U11: 8016.9231 | V11: =ROUND(T11,3) -> 3714.183 | W11: =ROUND(S11,3) -> 5865.553 | X11: =ROUND(U11,3) -> 8016.923
A12: =K11 -> 2024Q1 | B12: =O11 -> 434.196 | C12: =P11 -> 519.689 | D12: =Q11 -> 605.182 | E12: =V11 -> 3714.183 | F12: =W11 -> 5865.553 | G12: =X11 -> 8016.923 | K12: 2024Q2 | L12: 553.21023 | M12: 464.96791 | N12: 641.45255 | O12: =ROUND(M12,3) -> 464.968 | P12: =ROUND(L12,3) -> 553.21 | Q12: =ROUND(N12,3) -> 641.453 | R12: =K12 -> 2024Q2 | S12: 6030.6461 | T12: 3757.5741 | U12: 8303.7182 | V12: =ROUND(T12,3) -> 3757.574 | W12: =ROUND(S12,3) -> 6030.646 | X12: =ROUND(U12,3) -> 8303.718
A13: =K12 -> 2024Q2 | B13: =O12 -> 464.968 | C13: =P12 -> 553.21 | D13: =Q12 -> 641.453 | E13: =V12 -> 3757.574 | F13: =W12 -> 6030.646 | G13: =X12 -> 8303.718 | K13: 2024Q3 | L13: 554.4992 | M13: 463.85248 | N13: 645.14591 | O13: =ROUND(M13,3) -> 463.852 | P13: =ROUND(L13,3) -> 554.499 | Q13: =ROUND(N13,3) -> 645.146 | R13: =K13 -> 2024Q3 | S13: 5998.2439 | T13: 3609.6623 | U13: 8386.8254 | V13: =ROUND(T13,3) -> 3609.662 | W13: =ROUND(S13,3) -> 5998.244 | X13: =ROUND(U13,3) -> 8386.825
A14: =K13 -> 2024Q3 | B14: =O13 -> 463.852 | C14: =P13 -> 554.499 | D14: =Q13 -> 645.146 | E14: =V13 -> 3609.662 | F14: =W13 -> 5998.244 | G14: =X13 -> 8386.825 | K14: 2024Q4 | L14: 556.04009 | M14: 463.28166 | N14: 648.79852 | O14: =ROUND(M14,3) -> 463.282 | P14: =ROUND(L14,3) -> 556.04 | Q14: =ROUND(N14,3) -> 648.799 | R14: =K14 -> 2024Q4 | S14: 5960.1176 | T14: 3461.3604 | U14: 8458.8748 | V14: =ROUND(T14,3) -> 3461.36 | W14: =ROUND(S14,3) -> 5960.118 | X14: =ROUND(U14,3) -> 8458.875
A15: =K14 -> 2024Q4 | B15: =O14 -> 463.282 | C15: =P14 -> 556.04 | D15: =Q14 -> 648.799 | E15: =V14 -> 3461.36 | F15: =W14 -> 5960.118 | G15: =X14 -> 8458.875 | K15: 2025Q1 | L15: 518.20557 | M15: 423.58596 | N15: 612.82518 | O15: =ROUND(M15,3) -> 423.586 | P15: =ROUND(L15,3) -> 518.206 | Q15: =ROUND(N15,3) -> 612.825 | R15: =K15 -> 2025Q1 | S15: 6007.4449 | T15: 3403.1689 | U15: 8611.7209 | V15: =ROUND(T15,3) -> 3403.169 | W15: =ROUND(S15,3) -> 6007.445 | X15: =ROUND(U15,3) -> 8611.721
A16: =K15 -> 2025Q1 | B16: =O15 -> 423.586 | C16: =P15 -> 518.206 | D16: =Q15 -> 612.825 | E16: =V15 -> 3403.169 | F16: =W15 -> 6007.445 | G16: =X15 -> 8611.721 | K16: 2025Q2 | L16: 552.111 | M16: 455.84629 | N16: 648.37571 | O16: =ROUND(M16,3) -> 455.846 | P16: =ROUND(L16,3) -> 552.111 | Q16: =ROUND(N16,3) -> 648.376 | R16: =K16 -> 2025Q2 | S16: 6172.5387 | T16: 3466.8558 | U16: 8878.2216 | V16: =ROUND(T16,3) -> 3466.856 | W16: =ROUND(S16,3) -> 6172.539 | X16: =ROUND(U16,3) -> 8878.222
A17: =K16 -> 2025Q2 | B17: =O16 -> 455.846 | C17: =P16 -> 552.111 | D17: =Q16 -> 648.376 | E17: =V16 -> 3466.856 | F17: =W16 -> 6172.539 | G17: =X16 -> 8878.222 | K17: 2025Q3 | L17: 553.76468 | M17: 456.04233 | N17: 651.48703 | O17: =ROUND(M17,3) -> 456.042 | P17: =ROUND(L17,3) -> 553.765 | Q17: =ROUND(N17,3) -> 651.487 | R17: =K17 -> 2025Q3 | S17: 6140.1366 | T17: 3336.7126 | U17: 8943.5606 | V17: =ROUND(T17,3) -> 3336.713 | W17: =ROUND(S17,3) -> 6140.137 | X17: =ROUND(U17,3) -> 8943.561
A18: =K17 -> 2025Q3 | B18: =O17 -> 456.042 | C18: =P17 -> 553.765 | D18: =Q17 -> 651.487 | E18: =V17 -> 3336.713 | F18: =W17 -> 6140.137 | G18: =X17 -> 8943.561 | K18: 2025Q4 | L18: 555.65165 | M18: 456.63513 | N18: 654.66816 | O18: =ROUND(M18,3) -> 456.635 | P18: =ROUND(L18,3) -> 555.652 | Q18: =ROUND(N18,3) -> 654.668 | R18: =K18 -> 2025Q4 | S18: 6102.0104 | T18: 3204.1401 | U18: 8999.8807 | V18: =ROUND(T18,3) -> 3204.14 | W18: =ROUND(S18,3) -> 6102.01 | X18: =ROUND(U18,3) -> 8999.881
A19: =K18 -> 2025Q4 | B19: =O18 -> 456.635 | C19: =P18 -> 555.652 | D19: =Q18 -> 654.668 | E19: =V18 -> 3204.14 | F19: =W18 -> 6102.01 | G19: =X18 -> 8999.881 | K19: 2026Q1 | L19: 518.14553 | M19: 417.97799 | N19: 618.31307 | O19: =ROUND(M19,3) -> 417.978 | P19: =ROUND(L19,3) -> 518.146 | Q19: =ROUND(N19,3) -> 618.313 | R19: =K19 -> 2026Q1 | S19: 6149.3377 | T19: 3160.0035 | U19: 9138.6718 | V19: =ROUND(T19,3) -> 3160.004 | W19: =ROUND(S19,3) -> 6149.338 | X19: =ROUND(U19,3) -> 9138.672
A20: =K19 -> 2026Q1 | B20: =O19 -> 417.978 | C20: =P19 -> 518.146 | D20: =Q19 -> 618.313 | E20: =V19 -> 3160.004 | F20: =W19 -> 6149.338 | G20: =X19 -> 9138.672 | K20: 2026Q2 | L20: 552.36259 | M20: 451.16982 | N20: 653.55536 | O20: =ROUND(M20,3) -> 451.17 | P20: =ROUND(L20,3) -> 552.363 | Q20: =ROUND(N20,3) -> 653.555 | R20: =K20 -> 2026Q2 | S20: 6314.4315 | T20: 3236.3501 | U20: 9392.5128 | V20: =ROUND(T20,3) -> 3236.35 | W20: =ROUND(S20,3) -> 6314.431 | X20: =ROUND(U20,3) -> 9392.513
A21: =K20 -> 2026Q2 | B21: =O20 -> 451.17 | C21: =P20 -> 552.363 | D21: =Q20 -> 653.555 | E21: =V20 -> 3236.35 | F21: =W20 -> 6314.431 | G21: =X20 -> 9392.513 | K21: 2026Q3 | L21: 554.31197 | M21: 452.20484 | N21: 656.4191 | O21: =ROUND(M21,3) -> 452.205 | P21: =ROUND(L21,3) -> 554.312 | Q21: =ROUND(N21,3) -> 656.419 | R21: =K21 -> 2026Q3 | S21: 6282.0293 | T21: 3117.6888 | U21: 9446.3699 | V21: =ROUND(T21,3) -> 3117.689 | W21: =ROUND(S21,3) -> 6282.029 | X21: =ROUND(U21,3) -> 9446.37
A22: =K21 -> 2026Q3 | B22: =O21 -> 452.205 | C22: =P21 -> 554.312 | D22: =Q21 -> 656.419 | E22: =V21 -> 3117.689 | F22: =W21 -> 6282.029 | G22: =X21 -> 9446.37 | K22: 2026Q4 | L22: 556.47954 | M22: 453.55603 | N22: 659.40306 | O22: =ROUND(M22,3) -> 453.556 | P22: =ROUND(L22,3) -> 556.48 | Q22: =ROUND(N22,3) -> 659.403 | R22: =K22 -> 2026Q4 | S22: 6243.9031 | T22: 2995.5932 | U22: 9492.2131 | V22: =ROUND(T22,3) -> 2995.593 | W22: =ROUND(S22,3) -> 6243.903 | X22: =ROUND(U22,3) -> 9492.213
A23: =K22 -> 2026Q4 | B23: =O22 -> 453.556 | C23: =P22 -> 556.48 | D23: =Q22 -> 659.403 | E23: =V22 -> 2995.593 | F23: =W22 -> 6243.903 | G23: =X22 -> 9492.213 | K23: 2027Q1 | L23: 519.2397 | M23: 415.58657 | N23: 622.89282 | O23: =ROUND(M23,3) -> 415.587 | P23: =ROUND(L23,3) -> 519.24 | Q23: =ROUND(N23,3) -> 622.893 | R23: =K23 -> 2027Q1 | S23: 6291.2304 | T23: 2961.0678 | U23: 9621.3931 | V23: =ROUND(T23,3) -> 2961.068 | W23: =ROUND(S23,3) -> 6291.23 | X23: =ROUND(U23,3) -> 9621.393
... A34: =K33 -> 2029Q3 | B34: =O33 -> 453.6 | C34: =P33 -> 561.44 | D34: =Q33 -> 669.281 | E34: =V33 -> 2648.811 | F34: =W33 -> 6707.708 | G34: =X33 -> 10766.605 | K34: 2029Q4 | L34: 564.16947 | M34: 456.10898 | N34: 672.22997 | O34: =ROUND(M34,3) -> 456.109 | P34: =ROUND(L34,3) -> 564.169 | Q34: =ROUND(N34,3) -> 672.23 | R34: =K34 -> 2029Q4 | S34: 6669.5815 | T34: 2544.8861 | U34: 10794.277 | V34: =ROUND(T34,3) -> 2544.886 | W34: =ROUND(S34,3) -> 6669.581 | X34: =ROUND(U34,3) -> 10794.277
A35: =K34 -> 2029Q4 | B35: =O34 -> 456.109 | C35: =P34 -> 564.169 | D35: =Q34 -> 672.23 | E35: =V34 -> 2544.886 | F35: =W34 -> 6669.581 | G35: =X34 -> 10794.277
A38: Mean | C38: =AVERAGE(C4:C35) -> 548.19231 | F38: =AVERAGE(F4:F35) -> 6176.8798
A41: CIBCCA (Minus 0.5 Standard Deviation) | K41: CIBCCA (Minus 1 Standard Deviation)
B42: ACSS +USBE | E42: LVTS | L42: ACSS +USBE | O42: LVTS
A43: Year | B43: Lower Bound | C43: Forecast Minus Half A Standard Deviation (billions) | D43: Upper Bound | E43: Lower Bound | F43: =C43 -> Forecast Minus Half A Standard Deviation (billions) | G43: Upper Bound | K43: Year | L43: Lower Bound | M43: Forecast Minus One Standard Deviation (billions) | N43: Upper Bound | O43: Lower Bound | P43: =M43 -> Forecast Minus One Standard Deviation (billions) | Q43: Upper Bound
A44: =A4 -> 2022Q1 | C44: =ROUND(C4-((D4-C4)*(0.5/2)),3) -> 520.408 | F44: =ROUND(F4-((G4-F4)*(0.5/2)),3) -> 5434.54 | K44: =A4 -> 2022Q1 | M44: =ROUND(C4-((D4-C4)*(1/2)),3) -> 512.483 | P44: =ROUND(F4-((G4-F4)*(1/2)),3) -> 5278.41
A45: =A5 -> 2022Q2 | C45: =ROUND(C5-((D5-C5)*(0.5/2)),3) -> 549.312 | F45: =ROUND(F5-((G5-F5)*(0.5/2)),3) -> 5514.983 | K45: =A5 -> 2022Q2 | M45: =ROUND(C5-((D5-C5)*(1/2)),3) -> 537.828 | P45: =ROUND(F5-((G5-F5)*(1/2)),3) -> 5280.383
A46: =A6 -> 2022Q3 | C46: =ROUND(C6-((D6-C6)*(0.5/2)),3) -> 547.149 | F46: =ROUND(F6-((G6-F6)*(0.5/2)),3) -> 5419.045 | K46: =A6 -> 2022Q3 | M46: =ROUND(C6-((D6-C6)*(1/2)),3) -> 533.217 | P46: =ROUND(F6-((G6-F6)*(1/2)),3) -> 5122.8
A47: =A7 -> 2022Q4 | C47: =ROUND(C7-((D7-C7)*(0.5/2)),3) -> 545.854 | F47: =ROUND(F7-((G7-F7)*(0.5/2)),3) -> 5328.549 | K47: =A7 -> 2022Q4 | M47: =ROUND(C7-((D7-C7)*(1/2)),3) -> 530.039 | P47: =ROUND(F7-((G7-F7)*(1/2)),3) -> 4980.513
A48: =A8 -> 2023Q1 | C48: =ROUND(C8-((D8-C8)*(0.5/2)),3) -> 505.592 | F48: =ROUND(F8-((G8-F8)*(0.5/2)),3) -> 5330.423 | K48: =A8 -> 2023Q1 | M48: =ROUND(C8-((D8-C8)*(1/2)),3) -> 488.256 | P48: =ROUND(F8-((G8-F8)*(1/2)),3) -> 4937.108
A49: =A9 -> 2023Q2 | C49: =ROUND(C9-((D9-C9)*(0.5/2)),3) -> 537.375 | F49: =ROUND(F9-((G9-F9)*(0.5/2)),3) -> 5454.814 | K49: =A9 -> 2023Q2 | M49: =ROUND(C9-((D9-C9)*(1/2)),3) -> 518.776 | P49: =ROUND(F9-((G9-F9)*(1/2)),3) -> 5020.852
A50: =A10 -> 2023Q3 | C50: =ROUND(C10-((D10-C10)*(0.5/2)),3) -> 537.147 | F50: =ROUND(F10-((G10-F10)*(0.5/2)),3) -> 5385.222 | K50: =A10 -> 2023Q3 | M50: =ROUND(C10-((D10-C10)*(1/2)),3) -> 517.479 | P50: =ROUND(F10-((G10-F10)*(1/2)),3) -> 4914.085
A51: =A11 -> 2023Q4 | C51: =ROUND(C11-((D11-C11)*(0.5/2)),3) -> 537.346 | F51: =ROUND(F11-((G11-F11)*(0.5/2)),3) -> 5312.637 | K51: =A11 -> 2023Q4 | M51: =ROUND(C11-((D11-C11)*(1/2)),3) -> 516.763 | P51: =ROUND(F11-((G11-F11)*(1/2)),3) -> 4807.047
A52: =A12 -> 2024Q1 | C52: =ROUND(C12-((D12-C12)*(0.5/2)),3) -> 498.316 | F52: =ROUND(F12-((G12-F12)*(0.5/2)),3) -> 5327.711 | K52: =A12 -> 2024Q1 | M52: =ROUND(C12-((D12-C12)*(1/2)),3) -> 476.943 | P52: =ROUND(F12-((G12-F12)*(1/2)),3) -> 4789.868
A53: =A13 -> 2024Q2 | C53: =ROUND(C13-((D13-C13)*(0.5/2)),3) -> 531.149 | F53: =ROUND(F13-((G13-F13)*(0.5/2)),3) -> 5462.378 | K53: =A13 -> 2024Q2 | M53: =ROUND(C13-((D13-C13)*(1/2)),3) -> 509.089 | P53: =ROUND(F13-((G13-F13)*(1/2)),3) -> 4894.11
A54: =A14 -> 2024Q3 | C54: =ROUND(C14-((D14-C14)*(0.5/2)),3) -> 531.837 | F54: =ROUND(F14-((G14-F14)*(0.5/2)),3) -> 5401.099 | K54: =A14 -> 2024Q3 | M54: =ROUND(C14-((D14-C14)*(1/2)),3) -> 509.176 | P54: =ROUND(F14-((G14-F14)*(1/2)),3) -> 4803.954
...

Sheet CCDQCA
A1: CCDQCA | L1: ACSS | S1: LVTS
B2: ACSS +USBE | E2: LVTS | L2: Point Forecast | M2: Lo 95 | N2: Hi 95 | O2: Lo 95 | P2: Point Forecast | Q2: Hi 95 | S2: Point Forecast | T2: Lo 95 | U2: Hi 95 | V2: Lo 95 | W2: Point Forecast | X2: Hi 95
A3: Year | B3: Lower Bound | C3: Value Forecast (billions) | D3: Upper Bound | E3: Lower Bound | F3: Value Forecast (billions) | G3: Upper Bound | K3: 2022Q1 | L3: 204.42989 | M3: 190.56894 | N3: 218.29085 | O3: =ROUND(M3,3) -> 190.569 | P3: =ROUND(L3,3) -> 204.43 | Q3: =ROUND(N3,3) -> 218.291 | R3: =K3 -> 2022Q1 | S3: 1297.8885 | T3: 1075.7189 | U3: 1520.058 | V3: =ROUND(T3,3) -> 1075.719 | W3: =ROUND(S3,3) -> 1297.888 | X3: =ROUND(U3,3) -> 1520.058
A4: =K3 -> 2022Q1 | B4: =O3 -> 190.569 | C4: =P3 -> 204.43 | D4: =Q3 -> 218.291 | E4: =V3 -> 1075.719 | F4: =W3 -> 1297.888 | G4: =X3 -> 1520.058 | K4: 2022Q2 | L4: 221.70004 | M4: 205.78967 | N4: 237.61042 | O4: =ROUND(M4,3) -> 205.79 | P4: =ROUND(L4,3) -> 221.7 | Q4: =ROUND(N4,3) -> 237.61 | R4: =K4 -> 2022Q2 | S4: 1315.8361 | T4: 1052.5026 | U4: 1579.1696 | V4: =ROUND(T4,3) -> 1052.503 | W4: =ROUND(S4,3) -> 1315.836 | X4: =ROUND(U4,3) -> 1579.17
A5: =K4 -> 2022Q2 | B5: =O4 -> 205.79 | C5: =P4 -> 221.7 | D5: =Q4 -> 237.61 | E5: =V4 -> 1052.503 | F5: =W4 -> 1315.836 | G5: =X4 -> 1579.17 | I5: =SUM(F5:F8) -> 5290.65 | K5: 2022Q3 | L5: 214.28926 | M5: 197.01751 | N5: 231.561 | O5: =ROUND(M5,3) -> 197.018 | P5: =ROUND(L5,3) -> 214.289 | Q5: =ROUND(N5,3) -> 231.561 | R5: =K5 -> 2022Q3 | S5: 1301.2795 | T5: 1005.0446 | U5: 1597.5145 | V5: =ROUND(T5,3) -> 1005.045 | W5: =ROUND(S5,3) -> 1301.28 | X5: =ROUND(U5,3) -> 1597.514
